tools/gdbinit:21: Error in sourced command file:
firmware.elf: Datei oder Verzeichnis nicht gefunden.
Traceback (most recent call last):
  File "<string>", line 3, in <module>
gdb.error: localhost:3333: Die Wartezeit f端r die Verbindung ist abgelaufen.
tools/gdbinit:54: Error in sourced command file:
Error while executing Python code.
main () at main.c:45
Haltepunkt 1 at 0x80001ac: file main.c, line 39.
Anmerkung: Hardware-Haltepunkte f端r Nur-Lesen-Adressen werden automatisch benutzt.
target halted due to debug-request, current mode: Thread 
xPSR: 0x01000000 pc: 0x08000678 msp: 0x20020000

Breakpoint 1, main () at main.c:39
ss_pwm_init (pin_id=pin_id@entry=0x0, frequency=frequency@entry=0x3e8, fsys=fsys@entry=0xf42400) at ss/src/ss_pwm.c:143
$1 = 0xc00
$2 = 0xc00
$3 = 0x40000c00
$4 = 1000000000000000000110000000000
$5 = 0x40000c00
Warnung: Source file is more recent than executable.
Error in sys.excepthook:
Traceback (most recent call last):
  File "/usr/lib/python3/dist-packages/apport_python_hook.py", line 34, in apport_excepthook
    def apport_excepthook(exc_type, exc_obj, exc_tb):
KeyboardInterrupt

Original exception was:
Traceback (most recent call last):
  File "<string>", line 3, in <module>
gdb.error: localhost:3333: Die Wartezeit f端r die Verbindung ist abgelaufen.
tools/gdbinit:54: Error in sourced command file:
Error while executing Python code.
Warnung: Source file is more recent than executable.
Error in sys.excepthook:
Traceback (most recent call last):
  File "/usr/lib/python3/dist-packages/apport_python_hook.py", line 34, in apport_excepthook
    def apport_excepthook(exc_type, exc_obj, exc_tb):
KeyboardInterrupt

Original exception was:
Traceback (most recent call last):
  File "<string>", line 3, in <module>
gdb.error: localhost:3333: Die Wartezeit f端r die Verbindung ist abgelaufen.
tools/gdbinit:54: Error in sourced command file:
Error while executing Python code.
